Workbook
Name holidays: Holidays!$A$2:$A$937
Name IQ_CH: 110000
Name IQ_CQ: 5000
Name IQ_CY: 10000
Name IQ_DAILY: 500000
Name IQ_FH: 100000
Name IQ_FQ: 500
Name IQ_FY: 1000
Name IQ_LTM: 2000
Name IQ_MONTH: 15000
Name IQ_NTM: 6000
Name IQ_WEEK: 50000
Name IQ_YTD: 3000

Sheet Summary
A5: x | B5: Dates | E5: 46022 | F5: 46112 | G5: =+EOMONTH(F5,1) -> 46142 | H5: =+EOMONTH(G5,1) -> 46173 | I5: =+EOMONTH(H5,1) -> 46203 | J5: =+EOMONTH(I5,1) -> 46234 | K5: =+EOMONTH(J5,1) -> 46265 | L5: =+EOMONTH(K5,1) -> 46295 | M5: =+EOMONTH(L5,1) -> 46326 | N5: =+EOMONTH(M5,1) -> 46356 | ... EG5: =+EOMONTH(EF5,1) -> 50099
B6: Year | C6: [ - ] | F6: =+YEAR(F5) -> 2026 | G6: =+YEAR(G5) -> 2026 | H6: =+YEAR(H5) -> 2026 | I6: =+YEAR(I5) -> 2026 | J6: =+YEAR(J5) -> 2026 | K6: =+YEAR(K5) -> 2026 | L6: =+YEAR(L5) -> 2026 | M6: =+YEAR(M5) -> 2026 | ... EG6: =+YEAR(EG5) -> 2037
B7: CDI | C7: [% p.m.] | G7: =+INDEX(Macro!$C:$C,MATCH(G$5,Macro!$B:$B,0)) -> 0.011435906 | H7: =+INDEX(Macro!$C:$C,MATCH(H$5,Macro!$B:$B,0)) -> 0.011318174 | I7: =+INDEX(Macro!$C:$C,MATCH(I$5,Macro!$B:$B,0)) -> 0.011237146 | J7: =+INDEX(Macro!$C:$C,MATCH(J$5,Macro!$B:$B,0)) -> 0.011141293 | K7: =+INDEX(Macro!$C:$C,MATCH(K$5,Macro!$B:$B,0)) -> 0.011037955 | L7: =+INDEX(Macro!$C:$C,MATCH(L$5,Macro!$B:$B,0)) -> 0.010949286 | M7: =+INDEX(Macro!$C:$C,MATCH(M$5,Macro!$B:$B,0)) -> 0.010867932 | N7: =+INDEX(Macro!$C:$C,MATCH(N$5,Macro!$B:$B,0)) -> 0.010801316 | ... EG7: =+INDEX(Macro!$C:$C,MATCH(EG$5,Macro!$B:$B,0)) -> 0.010727241
B8: =B7 & " Factor" -> CDI Factor | C8: [ - ] | F8: 1 | G8: =+F8*(1+G7) -> 1.0114359 | H8: =+G8*(1+H7) -> 1.0228835 | I8: =+H8*(1+I7) -> 1.0343778 | J8: =+I8*(1+J7) -> 1.0459021 | K8: =+J8*(1+K7) -> 1.0574467 | L8: =+K8*(1+L7) -> 1.069025 | M8: =+L8*(1+M7) -> 1.0806431 | N8: =+M8*(1+N7) -> 1.0923155 | ... EG8: =+EF8*(1+EG7) -> 3.9963239
B9: IPCA | C9: [% p.m.] | G9: =+(1+INDEX(Macro!$F:$F,MATCH(G5,Macro!$B:$B,0)))^(1/12)-1 -> 0.0032716496 | H9: =+(1+INDEX(Macro!$F:$F,MATCH(H5,Macro!$B:$B,0)))^(1/12)-1 -> 0.0032716496 | I9: =+(1+INDEX(Macro!$F:$F,MATCH(I5,Macro!$B:$B,0)))^(1/12)-1 -> 0.0032716496 | J9: =+(1+INDEX(Macro!$F:$F,MATCH(J5,Macro!$B:$B,0)))^(1/12)-1 -> 0.0036706473 | K9: =+(1+INDEX(Macro!$F:$F,MATCH(K5,Macro!$B:$B,0)))^(1/12)-1 -> 0.0036706473 | L9: =+(1+INDEX(Macro!$F:$F,MATCH(L5,Macro!$B:$B,0)))^(1/12)-1 -> 0.0036706473 | M9: =+(1+INDEX(Macro!$F:$F,MATCH(M5,Macro!$B:$B,0)))^(1/12)-1 -> 0.0036706473 | N9: =+(1+INDEX(Macro!$F:$F,MATCH(N5,Macro!$B:$B,0)))^(1/12)-1 -> 0.003851442 | ... CB9: =+(1+INDEX(Macro!$F:$F,MATCH(CB5,Macro!$B:$B,0)))^(1/12)-1 -> 0.0048108117 | CC9: =+CB9 -> 0.0048108117 | CD9: =+CC9 -> 0.0048108117 | CE9: =+CD9 -> 0.0048108117 | CF9: =+CE9 -> 0.0048108117 | CG9: =+CF9 -> 0.0048108117 | CH9: =+CG9 -> 0.0048108117 | CI9: =+CH9 -> 0.0048108117 | CJ9: =+CI9 -> 0.0048108117 | ... EG9: =+EF9 -> 0.0048108117
B10: =B9 & " Factor" -> IPCA Factor | C10: [ - ] | F10: 1 | G10: =+F10*(1+G9) -> 1.0032716 | H10: =+G10*(1+H9) -> 1.006554 | I10: =+H10*(1+I9) -> 1.0098471 | J10: =+I10*(1+J9) -> 1.0135539 | K10: =+J10*(1+K9) -> 1.0172743 | L10: =+K10*(1+L9) -> 1.0210083 | M10: =+L10*(1+M9) -> 1.0247561 | N10: =+M10*(1+N9) -> 1.0287029 | ... EG10: =+EF10*(1+EG9) -> 1.8066002
B11: Selic | C11: [% p.m.] | G11: =+G7 -> 0.011435906 | H11: =+H7 -> 0.011318174 | I11: =+I7 -> 0.011237146 | J11: =+J7 -> 0.011141293 | K11: =+K7 -> 0.011037955 | L11: =+L7 -> 0.010949286 | M11: =+M7 -> 0.010867932 | N11: =+N7 -> 0.010801316 | ... EG11: =+EG7 -> 0.010727241
B12: =B11 & " Factor" -> Selic Factor | C12: [ - ] | F12: 1 | G12: =+F12+G11 -> 1.0114359 | H12: =+G12+H11 -> 1.0227541 | I12: =+H12+I11 -> 1.0339912 | J12: =+I12+J11 -> 1.0451325 | K12: =+J12+K11 -> 1.0561705 | L12: =+K12+L11 -> 1.0671198 | M12: =+L12+M11 -> 1.0779877 | N12: =+M12+N11 -> 1.088789 | ... EG12: =+EF12+EG11 -> 2.3927285
A15: x | B15: Control Panel / Outputs
B18: Deal Level Assumptions | F18: =B133 -> Returns Summary | H18: =C133 -> FIDC | I18: =D133 -> Debtor | J18: =E133 -> CET | P18: FIDC | Debtor | CET IRR %
F19: =B134 -> IRR % | H19: =C134 -> 0.28011814 | I19: =D134 -> 0.29647614 | J19: =E134 -> 0.35930123 | P19: Check Size R$ k
B20: Disbursement to Debtor, Gross of Taxes | C20: [R$ k] | D20: =+I29 -> 45 | F20: =B135 -> IRR IPCA + % | H20: =C135 -> 0.22258845 | I20: =D135 -> 0.23823712 | J20: =E135 -> 0.29824005 | O20: =TEXT(C134,"0.0%")&" | "&TEXT(D134,"0.0%")&" | "&TEXT(E134,"0.0%") -> 28.0% | 29.6% | 35.9% | P20: 30 | Q20: =+($T$31-$P$31)/4+P20 -> 37.5 | R20: =+($T$31-$P$31)/4+Q20 -> 45 | S20: =+($T$31-$P$31)/4+R20 -> 52.5 | T20: 60
B21: Total Debt | C21: [R$ k] | D21: =+F180 -> 49.473334 | F21: =B136 -> IRR CDI + % | H21: =C136 -> 0.12720175 | I21: =D136 -> 0.14157296 | J21: =E136 -> 0.19689171 | O21: 12 | P21: 26.9% | 29.7% | 42.6% | Q21: 27.5% | 29.7% | 42.6% | R21: 27.8% | 29.7% | 42.6% | S21: 28.1% | 29.7% | 42.6% | T21: 28.3% | 29.7% | 42.6%
B22: Attachment Point LTV | C22: [%] | D22: 0.3 | F22: =B137 -> MOICx | H22: =C137 -> 1.6291691 | I22: =D137 -> 1.6820465 | J22: =E137 -> 1.8492544 | O22: =+O21+12 -> 24 | P22: 27.2% | 29.6% | 35.9% | Q22: 27.7% | 29.6% | 35.9% | R22: 28.0% | 29.6% | 35.9% | S22: 28.2% | 29.6% | 35.9% | T22: 28.4% | 29.6% | 35.9%
F23: =B138 -> Duration Yrs | H23: =C138 -> 1.9763736 | I23: =D138 -> 2.0027397 | J23: =E138 -> 2.0027397 | N23: Time to Settle | O23: =+O22+12 -> 36 | P23: 27.5% | 29.7% | 33.8% | Q23: 27.9% | 29.7% | 33.8% | R23: 28.2% | 29.7% | 33.8% | S23: 28.4% | 29.7% | 33.8% | T23: 28.6% | 29.7% | 33.8%
B24: Interest | F24: =B139 -> Gains R$ mm | H24: =C139 -> 32.111115 | I24: =D139 -> 33.743115 | J24: =E139 -> 38.21645 | N24: # months | O24: =+O23+12 -> 48 | P24: 27.7% | 29.7% | 32.8% | Q24: 28.1% | 29.7% | 32.8% | R24: 28.4% | 29.7% | 32.8% | S24: 28.6% | 29.7% | 32.8% | T24: 28.7% | 29.7% | 32.8%
B25: Annual Basis | C25: [% p.a.] | D25: =+I49 -> 0.29693736 | O25: =+O24+12 -> 60 | P25: 27.9% | 29.7% | 32.2% | Q25: 28.3% | 29.7% | 32.2% | R25: 28.5% | 29.7% | 32.2% | S25: 28.7% | 29.7% | 32.2% | T25: 28.8% | 29.7% | 32.2%
B26: Semiannual Basis | C26: [% p.s.] | D26: =+(1+D$25)^(1/2)-1 -> 0.13883158 | O26: =+O25+12 -> 72 | P26: 26.5% | 28.1% | 30.1% | Q26: 26.8% | 28.1% | 30.1% | R26: 27.0% | 28.1% | 30.1% | S26: 27.2% | 28.1% | 30.1% | T26: 27.3% | 28.1% | 30.1%
B27: Quarterly Basis | C27: [% p.q.] | D27: =+(1+D$25)^(1/4)-1 -> 0.067160521 | F27: Inputs Calculadora
B28: Monthly Basis | C28: [% p.m.] | D28: =+(1+D$25)^(1/12)-1 -> 0.021903571
F29: Valor do Crédito | H29: [R$ k] | I29: 45 | P29: FIDC | Debtor | CET IRR CDI + %
B30: Upfront Fees | F30: Pagamento de Juros | H30: {=+_xlfn.IFS(I30="Coupon",1,I30="Bullet",2)} -> 2 | I30: Bullet | P30: Check Size R$ k
B31: Lawyer Origination Fee | C31: [%] | D31: 0.03 | F31: Parcelas | H31: {=+_xlfn.IFS(I31="Mensal",1,I31="Trimestral",2,I31="Semestral",3,I31="Anual",4)} -> 1 | I31: Mensal | O31: =TEXT(C136,"0.0%")&" | "&TEXT(D136,"0.0%")&" | "&TEXT(E136,"0.0%") -> 12.7% | 14.2% | 19.7% | P31: 30 | Q31: =+($T$31-$P$31)/4+P31 -> 37.5 | R31: =+($T$31-$P$31)/4+Q31 -> 45 | S31: =+($T$31-$P$31)/4+R31 -> 52.5 | T31: 60
B32: BT Closing Fee | C32: [%] | D32: 0.03 | F32: Prazo (meses) | H32: {=+_xlfn.IFS(I32=12,1,I32=18,2,I32=24,3,I32=30,4,I32=36,5)} -> 3 | I32: 24 | O32: 12 | P32: 11.4% | 13.8% | 25.1% | Q32: 11.9% | 13.8% | 25.1% | R32: 12.2% | 13.8% | 25.1% | S32: 12.4% | 13.8% | 25.1% | T32: 12.6% | 13.8% | 25.1%
B33: Bank Issuance Fee | O33: 24 | P33: 12.0% | 14.2% | 19.7% | Q33: 12.4% | 14.2% | 19.7% | R33: 12.7% | 14.2% | 19.7% | S33: 12.9% | 14.2% | 19.7% | T33: 13.1% | 14.2% | 19.7%
B34: % flat | C34: [%] | D34: 0.0045 | N34: Time to Settle | O34: 36 | P34: 12.4% | 14.3% | 18.0% | Q34: 12.8% | 14.3% | 18.0% | R34: 13.0% | 14.3% | 18.0% | S34: 13.2% | 14.3% | 18.0% | T34: 13.3% | 14.3% | 18.0%
B35: Minimum Value | C35: [R$ k] | D35: =2*0 -> 0 | F35: Interest Build-Up | N35: # months | O35: 48 | P35: 12.6% | 14.3% | 17.1% | Q35: 13.0% | 14.3% | 17.1% | R35: 13.2% | 14.3% | 17.1% | S35: 13.4% | 14.3% | 17.1% | T35: 13.5% | 14.3% | 17.1%
O36: 60 | P36: 12.8% | 14.3% | 16.5% | Q36: 13.1% | 14.3% | 16.5% | R36: 13.3% | 14.3% | 16.5% | S36: 13.5% | 14.3% | 16.5% | T36: 13.6% | 14.3% | 16.5%
B37: Upfront Operational Costs | F37: Juros Base | H37: [% p.a.] | I37: 0.267 | J37: [% p.m.] | K37: =+(1+I37)^(1/12)-1 -> 0.019916735 | O37: 72 | P37: 11.5% | 12.9% | 14.7% | Q37: 11.8% | 12.9% | 14.7% | R37: 12.0% | 12.9% | 14.7% | S37: 12.1% | 12.9% | 14.7% | T37: 12.2% | 12.9% | 14.7%
B38: Escrow Opening Fee | C38: [R$ k] | D38: 0 | F38: Juros Teto | H38: [% p.a.] | I38: 0.33582152 | J38: [% p.m.] | K38: =+(1+I38)^(1/12)-1 -> 0.02442233
B39: RTD Register | C39: [R$ k] | D39: =+_xlfn.XLOOKUP(D20*10^3,'Comparativo RTD'!$B$10:$B$19,'Comparativo RTD'!$I$10:$I$19,,1)/10^3*0 -> 0
F40: Pagamento de Juros | H40: [% p.a.] | I40: =+($I$38-$I$37)*60% -> 0.041292912 | J40: [% p.m.] | K40: =+(1+I40)^(1/12)-1 -> 0.0033776185
B41: Recurring Operational Costs | F41: Ajustado c/ Switch | H41: [% p.a.] | I41: =$H30/4*I40 -> 0.020646456 | J41: [% p.m.] | K41: =$H30/4*K40 -> 0.0016888092
B42: Escrow Monthly Fee | C42: [R$ k/month] | D42: =68/10^3*1 -> 0.068
F43: Parcelas | H43: [% p.a.] | I43: =+($I$38-$I$37)*30% -> 0.020646456 | J43: [% p.m.] | K43: =+(1+I43)^(1/12)-1 -> 0.0017044682
B44: Taxes | F44: Ajustado c/ Switch | H44: [% p.a.] | I44: =$H31/4*I43 -> 0.005161614 | J44: [% p.m.] | K44: =$H31/4*K43 -> 0.00042611705
B45: IOF on Issuance | C45: [%] | D45: 0.03373
F46: Prazo (meses) | H46: [% p.a.] | I46: =+($I$38-$I$37)*10% -> 0.006882152 | J46: [% p.m.] | K46: =+(1+I46)^(1/12)-1 -> 0.00057171154
B47: Realization | F47: Ajustado c/ Switch | H47: [% p.a.] | I47: =$H32/5*I46 -> 0.0041292912 | J47: [% p.m.] | K47: =$H32/5*K46 -> 0.00034302692
B48: Time to Settle | C48: [# months] | D48: =+I32 -> 24
...

Sheet >

Sheet Comparativo RTD
B2: Comparativo RTD 2026 – CCB e Cessão Fiduciária (RJ x SP)
B4: Premissas
B5: RJ: CCB e cessão fiduciária tratadas como 2 registros separados de título/documento com valor declarado.
B6: SP: CCB na tabela de documentos com conteúdo financeiro; garantia fiduciária estimada por proxy do item de alienação fiduciária/leasing/reserva de domínio.
B7: Valores não incluem certidões, notificações, busca, páginas/vias extras ou despesas acessórias.
B9: Valor da CCB | C9: RJ – CCB | D9: RJ – cessão fiduciária | E9: RJ – total | F9: RJ – total % | G9: SP – CCB | H9: SP – garantia fiduciária | I9: SP – total | J9: SP – total %
B10: 10000 | C10: 650.69 | D10: 650.69 | E10: =C10+D10 -> 1301.38 | F10: =+E10/$B10 -> 0.130138 | G10: 404.56 | H10: 199.72 | I10: =G10+H10 -> 604.28 | J10: =+I10/$B10 -> 0.060428
B11: 20000 | C11: 976.85 | D11: 976.85 | E11: =C11+D11 -> 1953.7 | F11: =+E11/$B11 -> 0.097685 | G11: 614.96 | H11: 199.72 | I11: =G11+H11 -> 814.68 | J11: =+I11/$B11 -> 0.040734
B12: 30000 | C12: 1503.1 | D12: 1503.1 | E12: =C12+D12 -> 3006.2 | F12: =+E12/$B12 -> 0.10020667 | G12: 815.33 | H12: 199.72 | I12: =G12+H12 -> 1015.05 | J12: =+I12/$B12 -> 0.033835
B13: 40000 | C13: 2004.13 | D13: 2004.13 | E13: =C13+D13 -> 4008.26 | F13: =+E13/$B13 -> 0.1002065 | G13: 1015.71 | H13: 292.68 | I13: =G13+H13 -> 1308.39 | J13: =+I13/$B13 -> 0.03270975
B14: 50000 | C14: 2505.18 | D14: 2505.18 | E14: =C14+D14 -> 5010.36 | F14: =+E14/$B14 -> 0.1002072 | G14: 1015.71 | H14: 292.68 | I14: =G14+H14 -> 1308.39 | J14: =+I14/$B14 -> 0.0261678
B15: 60000 | C15: 2505.18 | D15: 2505.18 | E15: =C15+D15 -> 5010.36 | F15: =+E15/$B15 -> 0.083506 | G15: 1135.94 | H15: 292.68 | I15: =G15+H15 -> 1428.62 | J15: =+I15/$B15 -> 0.023810333
B16: 70000 | C16: 2806.13 | D16: 2806.13 | E16: =C16+D16 -> 5612.26 | F16: =+E16/$B16 -> 0.080175143 | G16: 1135.94 | H16: 292.68 | I16: =G16+H16 -> 1428.62 | J16: =+I16/$B16 -> 0.020408857
B17: 80000 | C17: 2806.13 | D17: 2806.13 | E17: =C17+D17 -> 5612.26 | F17: =+E17/$B17 -> 0.07015325 | G17: 1216.1 | H17: 385.63 | I17: =G17+H17 -> 1601.73 | J17: =+I17/$B17 -> 0.020021625
B18: 90000 | C18: 3007.8 | D18: 3007.8 | E18: =C18+D18 -> 6015.6 | F18: =+E18/$B18 -> 0.06684 | G18: 1216.1 | H18: 385.63 | I18: =G18+H18 -> 1601.73 | J18: =+I18/$B18 -> 0.017797
B19: 100000 | C19: 3007.8 | D19: 3007.8 | E19: =C19+D19 -> 6015.6 | F19: =+E19/$B19 -> 0.060156 | G19: 1296.24 | H19: 385.63 | I19: =G19+H19 -> 1681.87 | J19: =+I19/$B19 -> 0.0168187
B22: Observações
B23: Em RJ, a tabela consultada prevê desmembramento quando houver dois negócios jurídicos no mesmo documento.
B24: Em SP, o enquadramento de cessão fiduciária pode variar na prática do cartório; por isso o valor é estimativo.
B25: Fontes: RJ 4º RTD-RJ tabela 2026; SP CDT/RTD-SP tabela 2026.

Sheet Custo de Crédito BR
A1: Crédito PF — taxa média de juros e ICC (jan/2026)
A2: Tabela refeita com a nomenclatura corrigida: a coluna de custo agregado é ICC, não CET.
A4: Modalidade | B4: Série BCB usada | C4: Taxa média de juros (% a.a.) | D4: ICC (% a.a.) | E4: Observação
A5: Consignado público | B5: Crédito pessoal consignado – trabalhadores do setor público | C5: 0.2372 | D5: 0.2288 | E5: Sem proxy adicional.
A6: Consignado privado | B6: Crédito pessoal consignado – trabalhadores do setor privado | C6: 0.5736 | D6: 0.5157 | E6: Sem proxy adicional.
A7: Crédito clean | B7: Crédito pessoal não consignado | C7: 1.1813 | D7: 1.0039 | E7: Proxy BCB usado para “crédito clean”: crédito pessoal não consignado.
A8: Crédito com garantia em automóveis | B8: Aquisição de veículos | C8: 0.2771 | D8: 0.2696 | E8: Proxy BCB usado para “garantia em automóveis”: aquisição de veículos.
A11: Notas importantes
A12: • ICC = custo médio das operações em aberto na carteira; não é o CET contratual da operação individual.
A13: • Pela Resolução CMN 4.881/2020, o CET é uma taxa anual da operação individual e consolida juros, tarifas, tributos, seguros e outras despesas vinculadas.
A14: • “Crédito clean” foi aproximado pela série oficial do BCB de crédito pessoal não consignado.
A15: • “Crédito com garantia em automóveis” foi aproximado pela série oficial do BCB de aquisição de veículos.
A16: • Último dado usado nas séries: jan/2026.
A18: As URLs e os códigos das séries estão na aba “Base e fontes”.
A21: Base e fontes da tabela principal
A22: Os valores abaixo replicam o último ponto disponível (jan/2026) das séries públicas do Banco Central do Brasil.
A23: Modalidade | B23: Série BCB usada | C23: SGS juros | D23: Taxa média de juros (% a.a.) | E23: URL juros | F23: SGS ICC | G23: ICC (% a.a.) | H23: URL ICC | I23: Fonte conceitual | J23: Observação
A24: Consignado público | B24: Crédito pessoal consignado – trabalhadores do setor público | C24: 20745 | D24: 0.2372 | E24: https://api.bcb.gov.br/dados/serie/bcdata.sgs.20745/dados?formato=json | F24: 27676 | G24: 0.2288 | H24: https://api.bcb.gov.br/dados/serie/bcdata.sgs.27676/dados?formato=json | I24: https://opendata.bcb.gov.br/dataset/27676-average-cost-of-outstanding-loans---nonearmarked---households---payroll-deducted-personal-loa | J24: Sem proxy adicional.
A25: Consignado privado | B25: Crédito pessoal consignado – trabalhadores do setor privado | C25: 20744 | D25: 0.5736 | E25: https://api.bcb.gov.br/dados/serie/bcdata.sgs.20744/dados?formato=json | F25: 27675 | G25: 0.5157 | H25: https://api.bcb.gov.br/dados/serie/bcdata.sgs.27675/dados?formato=json | I25: https://opendata.bcb.gov.br/dataset/27675-average-cost-of-outstanding-loans---nonearmarked---households---payroll-deducted-personal-loa | J25: Sem proxy adicional.
A26: Crédito clean | B26: Crédito pessoal não consignado | C26: 20742 | D26: 1.1813 | E26: https://api.bcb.gov.br/dados/serie/bcdata.sgs.20742/dados?formato=json | F26: 27673 | G26: 1.0039 | H26: https://api.bcb.gov.br/dados/serie/bcdata.sgs.27673/dados?formato=json | I26: https://opendata.bcb.gov.br/dataset/27673-average-cost-of-outstanding-loans---nonearmarked---households---personal-credit | J26: Proxy BCB usado para “crédito clean”: crédito pessoal não consignado.
A27: Crédito com garantia em automóveis | B27: Aquisição de veículos | C27: 20749 | D27: 0.2771 | E27: https://api.bcb.gov.br/dados/serie/bcdata.sgs.20749/dados?formato=json | F27: 27680 | G27: 0.2696 | H27: https://api.bcb.gov.br/dados/serie/bcdata.sgs.27680/dados?formato=json | I27: https://opendata.bcb.gov.br/ne/dataset/27680-average-cost-of-outstanding-loans---nonearmarked---households---vehicles-financing | J27: Proxy BCB usado para “garantia em automóveis”: aquisição de veículos.
A29: Referência normativa para CET: https://www.bcb.gov.br/content/estabilidadefinanceira/especialnor/Resolu%C3%A7%C3%A3o4881.pdf
A32: Definições rápidas
A33: Termo | B33: Resumo | C33: URL
A34: CET | B34: Pela Resolução CMN 4.881/2020, o CET é uma taxa anual da operação individual que consolida juros, tarifas, tributos, seguros e outras despesas vinculadas. | C34: https://www.bcb.gov.br/content/estabilidadefinanceira/especialnor/Resolu%C3%A7%C3%A3o4881.pdf
A35: ICC | B35: Nas séries do BCB, o ICC é o custo médio das operações em aberto na carteira. É útil como visão agregada de custo, mas não substitui o CET contratual de cada operação. | C35: https://opendata.bcb.gov.br/dataset/27676-average-cost-of-outstanding-loans---nonearmarked---households---payroll-deducted-personal-loa
A36: Juros médios | B36: As séries de taxa média de juros refletem novas operações contratadas no período e são ponderadas pelo valor das concessões. | C36: https://dadosabertos.bcb.gov.br/dataset/20745-taxa-media-de-juros-das-operacoes-de-credito-com-recursos-livres---pessoas-fisicas---credito-
A37: Leitura correta da tabela | B37: A comparação abaixo é entre uma visão de fluxo (taxa média de juros das novas concessões) e uma visão de estoque/carteira (ICC). Por isso, a coluna de ICC não deve ser lida como CET. | C37: https://www.bcb.gov.br/content/estabilidadefinanceira/especialnor/Resolu%C3%A7%C3%A3o4881.pdf

Sheet >>

Sheet Macro
B7: Reference Date | C7: [date EoP] | D7: 46093
B8: Senior Tranche Interest | C8: [CDI + %] | D8: =Summary!#REF! -> #REF!
B9: Mezzanine Tranche Interest | C9: [CDI + %] | D9: =Summary!#REF! -> #REF!
J10: IPCA | N10: Selic
D11: Senior | E11: Mez
B12: Date | C12: CDI % p.m. | D12: CDI + % p.m. | E12: CDI + % p.m. | F12: IPCA | J12: Data | K12: Vértices | L12: Inflação Implícita | N12: Data | O12: Dias Corridos | P12: Preço/Taxa
B13: 44742 | C13: 0.01013541 | J13: =+$D$7+K13 -> 46219 | K13: 126 | L13: 0.039974 | N13: =+$D$7+O13 -> 46094 | O13: 1 | P13: 0.149
B14: 44773 | C14: 0.01084387 | D14: =+(1+C14)*(1+D$8)^(NETWORKDAYS(WORKDAY(B13,1,holidays),B14,holidays)/252)-1 -> #REF! | E14: =+(1+C14)*(1+D$9)^(NETWORKDAYS(WORKDAY(B13,1,holidays),B14,holidays)/252)-1 -> #REF! | J14: =+$D$7+K14 -> 46345 | K14: 252 | L14: 0.044948 | N14: =+$D$7+O14 -> 46098 | O14: 5 | P14: 0.1476
B15: 44804 | C15: 0.01118005 | D15: =+(1+C15)*(1+D$8)^(NETWORKDAYS(WORKDAY(B14,1,holidays),B15,holidays)/252)-1 -> #REF! | E15: =+(1+C15)*(1+D$9)^(NETWORKDAYS(WORKDAY(B14,1,holidays),B15,holidays)/252)-1 -> #REF! | J15: =+$D$7+K15 -> 46471 | K15: 378 | L15: 0.047209 | N15: =+$D$7+O15 -> 46099 | O15: 6 | P15: 0.1474
B16: 44834 | C16: 0.01071982 | D16: =+(1+C16)*(1+D$8)^(NETWORKDAYS(WORKDAY(B15,1,holidays),B16,holidays)/252)-1 -> #REF! | E16: =+(1+C16)*(1+D$9)^(NETWORKDAYS(WORKDAY(B15,1,holidays),B16,holidays)/252)-1 -> #REF! | J16: =+$D$7+K16 -> 46597 | K16: 504 | L16: 0.048486 | N16: =+$D$7+O16 -> 46100 | O16: 7 | P16: 0.1473
B17: 44865 | C17: 0.01020676 | D17: =+(1+C17)*(1+D$8)^(NETWORKDAYS(WORKDAY(B16,1,holidays),B17,holidays)/252)-1 -> #REF! | E17: =+(1+C17)*(1+D$9)^(NETWORKDAYS(WORKDAY(B16,1,holidays),B17,holidays)/252)-1 -> #REF! | J17: =+$D$7+K17 -> 46723 | K17: 630 | L17: 0.049409 | N17: =+$D$7+O17 -> 46101 | O17: 8 | P17: 0.1473
B18: 44895 | C18: 0.01020676 | D18: =+(1+C18)*(1+D$8)^(NETWORKDAYS(WORKDAY(B17,1,holidays),B18,holidays)/252)-1 -> #REF! | E18: =+(1+C18)*(1+D$9)^(NETWORKDAYS(WORKDAY(B17,1,holidays),B18,holidays)/252)-1 -> #REF! | J18: =+$D$7+K18 -> 46849 | K18: 756 | L18: 0.050243 | N18: =+$D$7+O18 -> 46102 | O18: 9 | P18: 0.1472
B19: 44926 | C19: 0.01174673 | D19: =+(1+C19)*(1+D$8)^(NETWORKDAYS(WORKDAY(B18,1,holidays),B19,holidays)/252)-1 -> #REF! | E19: =+(1+C19)*(1+D$9)^(NETWORKDAYS(WORKDAY(B18,1,holidays),B19,holidays)/252)-1 -> #REF! | J19: =+$D$7+K19 -> 46975 | K19: 882 | L19: 0.051089 | N19: =+$D$7+O19 -> 46105 | O19: 12 | P19: 0.1472
B20: 44957 | C20: 0.01071982 | D20: =+(1+C20)*(1+D$8)^(NETWORKDAYS(WORKDAY(B19,1,holidays),B20,holidays)/252)-1 -> #REF! | E20: =+(1+C20)*(1+D$9)^(NETWORKDAYS(WORKDAY(B19,1,holidays),B20,holidays)/252)-1 -> #REF! | J20: =+$D$7+K20 -> 47101 | K20: 1008 | L20: 0.051972 | N20: =+$D$7+O20 -> 46107 | O20: 14 | P20: 0.1471
B21: 44985 | C21: 0.00918141 | D21: =+(1+C21)*(1+D$8)^(NETWORKDAYS(WORKDAY(B20,1,holidays),B21,holidays)/252)-1 -> #REF! | E21: =+(1+C21)*(1+D$9)^(NETWORKDAYS(WORKDAY(B20,1,holidays),B21,holidays)/252)-1 -> #REF! | J21: =+$D$7+K21 -> 47227 | K21: 1134 | L21: 0.05288 | N21: =+$D$7+O21 -> 46109 | O21: 16 | P21: 0.1471
B22: 45016 | C22: 0.01174673 | D22: =+(1+C22)*(1+D$8)^(NETWORKDAYS(WORKDAY(B21,1,holidays),B22,holidays)/252)-1 -> #REF! | E22: =+(1+C22)*(1+D$9)^(NETWORKDAYS(WORKDAY(B21,1,holidays),B22,holidays)/252)-1 -> #REF! | J22: =+$D$7+K22 -> 47353 | K22: 1260 | L22: 0.053793 | N22: =+$D$7+O22 -> 46112 | O22: 19 | P22: 0.1471
B23: 45046 | C23: 0.00969396 | D23: =+(1+C23)*(1+D$8)^(NETWORKDAYS(WORKDAY(B22,1,holidays),B23,holidays)/252)-1 -> #REF! | E23: =+(1+C23)*(1+D$9)^(NETWORKDAYS(WORKDAY(B22,1,holidays),B23,holidays)/252)-1 -> #REF! | J23: =+$D$7+K23 -> 47479 | K23: 1386 | L23: 0.054686 | N23: =+$D$7+O23 -> 46113 | O23: 20 | P23: 0.1471
B24: 45077 | C24: 0.01071982 | D24: =+(1+C24)*(1+D$8)^(NETWORKDAYS(WORKDAY(B23,1,holidays),B24,holidays)/252)-1 -> #REF! | E24: =+(1+C24)*(1+D$9)^(NETWORKDAYS(WORKDAY(B23,1,holidays),B24,holidays)/252)-1 -> #REF! | J24: =+$D$7+K24 -> 47605 | K24: 1512 | L24: 0.05554 | N24: =+$D$7+O24 -> 46114 | O24: 21 | P24: 0.1471
B25: 45107 | C25: 0.01071982 | D25: =+(1+C25)*(1+D$8)^(NETWORKDAYS(WORKDAY(B24,1,holidays),B25,holidays)/252)-1 -> #REF! | E25: =+(1+C25)*(1+D$9)^(NETWORKDAYS(WORKDAY(B24,1,holidays),B25,holidays)/252)-1 -> #REF! | J25: =+$D$7+K25 -> 47731 | K25: 1638 | L25: 0.056339 | N25: =+$D$7+O25 -> 46123 | O25: 30 | P25: 0.1466
... B30: 45260 | C30: 0.00917769 | D30: =+(1+C30)*(1+D$8)^(NETWORKDAYS(WORKDAY(B29,1,holidays),B30,holidays)/252)-1 -> #REF! | E30: =+(1+C30)*(1+D$9)^(NETWORKDAYS(WORKDAY(B29,1,holidays),B30,holidays)/252)-1 -> #REF! | J30: =+$D$7+K30 -> 48361 | K30: 2268 | L30: 0.059282 | N30: =+$D$7+O30 -> 46130 | O30: 37 | P30: 0.1464
B31: 45291 | C31: 0.00940445 | D31: =+(1+C31)*(1+D$8)^(NETWORKDAYS(WORKDAY(B30,1,holidays),B31,holidays)/252)-1 -> #REF! | E31: =+(1+C31)*(1+D$9)^(NETWORKDAYS(WORKDAY(B30,1,holidays),B31,holidays)/252)-1 -> #REF! | J31: =+$D$7+K31 -> 48487 | K31: =+K30+($K$30-$K$29) -> 2394 | L31: =+L30 -> 0.059282 | N31: =+$D$7+O31 -> 46137 | O31: 44 | P31: 0.1463
B32: 45322 | C32: 0.00922548 | D32: =+(1+C32)*(1+D$8)^(NETWORKDAYS(WORKDAY(B31,1,holidays),B32,holidays)/252)-1 -> #REF! | E32: =+(1+C32)*(1+D$9)^(NETWORKDAYS(WORKDAY(B31,1,holidays),B32,holidays)/252)-1 -> #REF! | J32: =+$D$7+K32 -> 48613 | K32: =+K31+($K$30-$K$29) -> 2520 | L32: =+L31 -> 0.059282 | N32: =+$D$7+O32 -> 46141 | O32: 48 | P32: 0.1462
B33: 45351 | C33: 0.00801996 | D33: =+(1+C33)*(1+D$8)^(NETWORKDAYS(WORKDAY(B32,1,holidays),B33,holidays)/252)-1 -> #REF! | E33: =+(1+C33)*(1+D$9)^(NETWORKDAYS(WORKDAY(B32,1,holidays),B33,holidays)/252)-1 -> #REF! | J33: =+$D$7+K33 -> 48739 | K33: =+K32+($K$30-$K$29) -> 2646 | L33: =+L32 -> 0.059282 | N33: =+$D$7+O33 -> 46142 | O33: 49 | P33: 0.1462
B34: 45382 | C34: 0.0087398 | D34: =+(1+C34)*(1+D$8)^(NETWORKDAYS(WORKDAY(B33,1,holidays),B34,holidays)/252)-1 -> #REF! | E34: =+(1+C34)*(1+D$9)^(NETWORKDAYS(WORKDAY(B33,1,holidays),B34,holidays)/252)-1 -> #REF! | J34: =+$D$7+K34 -> 48865 | K34: =+K33+($K$30-$K$29) -> 2772 | L34: =+L33 -> 0.059282 | N34: =+$D$7+O34 -> 46143 | O34: 50 | P34: 0.1462
B35: 45412 | C35: 0.00846925 | D35: =+(1+C35)*(1+D$8)^(NETWORKDAYS(WORKDAY(B34,1,holidays),B35,holidays)/252)-1 -> #REF! | E35: =+(1+C35)*(1+D$9)^(NETWORKDAYS(WORKDAY(B34,1,holidays),B35,holidays)/252)-1 -> #REF! | J35: =+$D$7+K35 -> 48991 | K35: =+K34+($K$30-$K$29) -> 2898 | L35: =+L34 -> 0.059282 | N35: =+$D$7+O35 -> 46147 | O35: 54 | P35: 0.1461
B36: 45443 | C36: 0.00833347 | D36: =+(1+C36)*(1+D$8)^(NETWORKDAYS(WORKDAY(B35,1,holidays),B36,holidays)/252)-1 -> #REF! | E36: =+(1+C36)*(1+D$9)^(NETWORKDAYS(WORKDAY(B35,1,holidays),B36,holidays)/252)-1 -> #REF! | J36: =+$D$7+K36 -> 49117 | K36: =+K35+($K$30-$K$29) -> 3024 | L36: =+L35 -> 0.059282 | N36: =+$D$7+O36 -> 46154 | O36: 61 | P36: 0.1456
B37: 45473 | C37: 0.00827917 | D37: =+(1+C37)*(1+D$8)^(NETWORKDAYS(WORKDAY(B36,1,holidays),B37,holidays)/252)-1 -> #REF! | E37: =+(1+C37)*(1+D$9)^(NETWORKDAYS(WORKDAY(B36,1,holidays),B37,holidays)/252)-1 -> #REF! | J37: =+$D$7+K37 -> 49243 | K37: =+K36+($K$30-$K$29) -> 3150 | L37: =+L36 -> 0.059282 | N37: =+$D$7+O37 -> 46156 | O37: 63 | P37: 0.1455
B38: 45504 | C38: 0.00867512 | D38: =+(1+C38)*(1+D$8)^(NETWORKDAYS(WORKDAY(B37,1,holidays),B38,holidays)/252)-1 -> #REF! | E38: =+(1+C38)*(1+D$9)^(NETWORKDAYS(WORKDAY(B37,1,holidays),B38,holidays)/252)-1 -> #REF! | J38: =+$D$7+K38 -> 49369 | K38: =+K37+($K$30-$K$29) -> 3276 | L38: =+L37 -> 0.059282 | N38: =+$D$7+O38 -> 46158 | O38: 65 | P38: 0.1453
B39: 45535 | C39: 0.00907122 | D39: =+(1+C39)*(1+D$8)^(NETWORKDAYS(WORKDAY(B38,1,holidays),B39,holidays)/252)-1 -> #REF! | E39: =+(1+C39)*(1+D$9)^(NETWORKDAYS(WORKDAY(B38,1,holidays),B39,holidays)/252)-1 -> #REF! | J39: =+$D$7+K39 -> 49495 | K39: =+K38+($K$30-$K$29) -> 3402 | L39: =+L38 -> 0.059282 | N39: =+$D$7+O39 -> 46162 | O39: 69 | P39: 0.1452
B40: 45565 | C40: 0.0079467 | D40: =+(1+C40)*(1+D$8)^(NETWORKDAYS(WORKDAY(B39,1,holidays),B40,holidays)/252)-1 -> #REF! | E40: =+(1+C40)*(1+D$9)^(NETWORKDAYS(WORKDAY(B39,1,holidays),B40,holidays)/252)-1 -> #REF! | J40: =+$D$7+K40 -> 49621 | K40: =+K39+($K$30-$K$29) -> 3528 | L40: =+L39 -> 0.059282 | N40: =+$D$7+O40 -> 46163 | O40: 70 | P40: 0.1451
B41: 45596 | C41: 0.00927958 | D41: =+(1+C41)*(1+D$8)^(NETWORKDAYS(WORKDAY(B40,1,holidays),B41,holidays)/252)-1 -> #REF! | E41: =+(1+C41)*(1+D$9)^(NETWORKDAYS(WORKDAY(B40,1,holidays),B41,holidays)/252)-1 -> #REF! | J41: =+$D$7+K41 -> 49747 | K41: =+K40+($K$30-$K$29) -> 3654 | L41: =+L40 -> 0.059282 | N41: =+$D$7+O41 -> 46164 | O41: 71 | P41: 0.145
B42: 45626 | C42: 0.00833477 | D42: =+(1+C42)*(1+D$8)^(NETWORKDAYS(WORKDAY(B41,1,holidays),B42,holidays)/252)-1 -> #REF! | E42: =+(1+C42)*(1+D$9)^(NETWORKDAYS(WORKDAY(B41,1,holidays),B42,holidays)/252)-1 -> #REF! | J42: =+$D$7+K42 -> 49873 | K42: =+K41+($K$30-$K$29) -> 3780 | L42: =+L41 -> 0.059282 | N42: =+$D$7+O42 -> 46170 | O42: 77 | P42: 0.1448
... B55: 46022 | C55: 0.01164123 | D55: =+(1+C55)*(1+D$8)^(NETWORKDAYS(WORKDAY(B54,1,holidays),B55,holidays)/252)-1 -> #REF! | E55: =+(1+C55)*(1+D$9)^(NETWORKDAYS(WORKDAY(B54,1,holidays),B55,holidays)/252)-1 -> #REF! | J55: =+$D$7+K55 -> 51511 | K55: =+K54+($K$30-$K$29) -> 5418 | L55: =+L54 -> 0.059282 | N55: =+$D$7+O55 -> 46213 | O55: 120 | P55: 0.143
B56: 46053 | C56: =+(1+_xlfn.XLOOKUP(B56,$N$13:$N$301,$P$13:$P$301,,1))^(1/12)-1 -> 0.011641575 | D56: =+(1+C56)*(1+D$8)^(1/12)-1 -> #REF! | E56: =+(1+C56)*(1+D$9)^(1/12)-1 -> #REF! | F56: =+_xlfn.XLOOKUP(B56,$J$13:$J$57,$L$13:$L$57,,1) -> 0.039974 | J56: =+$D$7+K56 -> 51637 | K56: =+K55+($K$30-$K$29) -> 5544 | L56: =+L55 -> 0.059282 | N56: =+$D$7+O56 -> 46218 | O56: 125 | P56: 0.1428
B57: 46081 | C57: =+(1+_xlfn.XLOOKUP(B57,$N$13:$N$301,$P$13:$P$301,,1))^(1/12)-1 -> 0.011641575 | D57: =+(1+C57)*(1+D$8)^(1/12)-1 -> #REF! | E57: =+(1+C57)*(1+D$9)^(1/12)-1 -> #REF! | F57: =+_xlfn.XLOOKUP(B57,$J$13:$J$57,$L$13:$L$57,,1) -> 0.039974 | J57: =+$D$7+K57 -> 51763 | K57: =+K56+($K$30-$K$29) -> 5670 | L57: =+L56 -> 0.059282 | N57: =+$D$7+O57 -> 46219 | O57: 126 | P57: 0.1427
B58: 46112 | C58: =+(1+_xlfn.XLOOKUP(B58,$N$13:$N$301,$P$13:$P$301,,1))^(1/12)-1 -> 0.011502064 | D58: =+(1+C58)*(1+D$8)^(1/12)-1 -> #REF! | E58: =+(1+C58)*(1+D$9)^(1/12)-1 -> #REF! | F58: =+_xlfn.XLOOKUP(B58,$J$13:$J$57,$L$13:$L$57,,1) -> 0.039974 | N58: =+$D$7+O58 -> 46227 | O58: 134 | P58: 0.1424
B59: 46142 | C59: =+(1+_xlfn.XLOOKUP(B59,$N$13:$N$301,$P$13:$P$301,,1))^(1/12)-1 -> 0.011435906 | D59: =+(1+C59)*(1+D$8)^(1/12)-1 -> #REF! | E59: =+(1+C59)*(1+D$9)^(1/12)-1 -> #REF! | F59: =+_xlfn.XLOOKUP(B59,$J$13:$J$57,$L$13:$L$57,,1) -> 0.039974 | N59: =+$D$7+O59 -> 46234 | O59: 141 | P59: 0.1422
B60: 46173 | C60: =+(1+_xlfn.XLOOKUP(B60,$N$13:$N$301,$P$13:$P$301,,1))^(1/12)-1 -> 0.011318174 | D60: =+(1+C60)*(1+D$8)^(1/12)-1 -> #REF! | E60: =+(1+C60)*(1+D$9)^(1/12)-1 -> #REF! | F60: =+_xlfn.XLOOKUP(B60,$J$13:$J$57,$L$13:$L$57,,1) -> 0.039974 | N60: =+$D$7+O60 -> 46235 | O60: 142 | P60: 0.1421
B61: 46203 | C61: =+(1+_xlfn.XLOOKUP(B61,$N$13:$N$301,$P$13:$P$301,,1))^(1/12)-1 -> 0.011237146 | D61: =+(1+C61)*(1+D$8)^(1/12)-1 -> #REF! | E61: =+(1+C61)*(1+D$9)^(1/12)-1 -> #REF! | F61: =+_xlfn.XLOOKUP(B61,$J$13:$J$57,$L$13:$L$57,,1) -> 0.039974 | N61: =+$D$7+O61 -> 46238 | O61: 145 | P61: 0.1421
B62: 46234 | C62: =+(1+_xlfn.XLOOKUP(B62,$N$13:$N$301,$P$13:$P$301,,1))^(1/12)-1 -> 0.011141293 | D62: =+(1+C62)*(1+D$8)^(1/12)-1 -> #REF! | E62: =+(1+C62)*(1+D$9)^(1/12)-1 -> #REF! | F62: =+_xlfn.XLOOKUP(B62,$J$13:$J$57,$L$13:$L$57,,1) -> 0.044948 | N62: =+$D$7+O62 -> 46245 | O62: 152 | P62: 0.1417
...

Sheet Holidays
A1: Data | B1: Dia da Semana | C1: Feriado
A2: 36892 | B2: segunda-feira | C2: Confraternização Universal
A3: 36948 | B3: segunda-feira | C3: Carnaval
A4: 36949 | B4: terça-feira | C4: Carnaval
A5: 36994 | B5: sexta-feira | C5: Paixão de Cristo
A6: 37002 | B6: sábado | C6: Tiradentes
A7: 37012 | B7: terça-feira | C7: Dia do Trabalho
A8: 37056 | B8: quinta-feira | C8: Corpus Christi
A9: 37141 | B9: sexta-feira | C9: Independência do Brasil
A10: 37176 | B10: sexta-feira | C10: Nossa Sr.a Aparecida - Padroeira do Brasil
A11: 37197 | B11: sexta-feira | C11: Finados
A12: 37210 | B12: quinta-feira | C12: Proclamação da República
A13: 37250 | B13: terça-feira | C13: Natal
... A937: 65374 | B937: quarta-feira | C937: Natal
